Workbook

Sheet scenarios
G1: Apply linear regression | L1: Calculate scalars for premise (year 2020 = 1)
A2: quicklime production, PFRK, milled, loose
A3: LCI parameters | B3: 2025 | C3: 2035 | E3: 2035 BAT-Worst | G3: 2020 | H3: 2025 | I3: 2030 | J3: 2035 | L3: 2020 | M3: 2025 | N3: 2030 | O3: 2035
A4: Limestone consumption | B4: =lcis!C4 -> 1.854 | C4: =lcis!D4 -> 1.818 | D4: =(C4-B4)/B4 -> -0.019417476 | E4: =lcis!E4 -> 1.89 | F4: =(E4-B4)/B4 -> 0.019417476 | G4: =B4 -> 1.854 | H4: =B4 -> 1.854 | I4: {=TREND($B4:$C4,$B$3:$C$3,I$3)} -> 1.836 | J4: {=TREND($B4:$C4,$B$3:$C$3,J$3)} -> 1.818 | L4: =1/(G4/$G4) -> 1 | M4: =1/(H4/$G4) -> 1 | N4: =1/(I4/$G4) -> 1.0098039 | O4: =1/(J4/$G4) -> 1.019802
A5: Heat consumption | B5: =lcis!C5 -> 3.7 | C5: =lcis!D5 -> 3.2 | D5: =(C5-B5)/B5 -> -0.13513514 | E5: =lcis!E5 -> 4.2 | F5: =(E5-B5)/B5 -> 0.13513514 | G5: =B5 -> 3.7 | H5: =B5 -> 3.7 | I5: {=TREND($B5:$C5,$B$3:$C$3,I$3)} -> 3.45 | J5: {=TREND($B5:$C5,$B$3:$C$3,J$3)} -> 3.2 | L5: See below by fuel type
A6: Electricity consumption | B6: =lcis!C6 -> 0.055 | C6: =lcis!D6 -> 0.03 | D6: =(C6-B6)/B6 -> -0.45454545 | E6: =lcis!E6 -> 0.08 | F6: =(E6-B6)/B6 -> 0.45454545 | G6: =B6 -> 0.055 | H6: =B6 -> 0.055 | I6: {=TREND($B6:$C6,$B$3:$C$3,I$3)} -> 0.0425 | J6: {=TREND($B6:$C6,$B$3:$C$3,J$3)} -> 0.03 | L6: =1/(G6/$G6) -> 1 | M6: =1/(H6/$G6) -> 1 | N6: =1/(I6/$G6) -> 1.2941176 | O6: =1/(J6/$G6) -> 1.8333333
A7: Electricity consumption, with CCS | B7: =lcis!C18+lcis!C19+lcis!C20 -> 0.21787778 | C7: =lcis!D18+lcis!D19+lcis!D20 -> 0.19093333 | D7: =(C7-B7)/B7 -> -0.1236677 | E7: =lcis!E18+lcis!E19+lcis!C20 -> 0.26232222 | F7: =(E7-B7)/B7 -> 0.20398796 | G7: =B7 -> 0.21787778 | H7: =B7 -> 0.21787778 | I7: {=TREND($B7:$C7,$B$3:$C$3,I$3)} -> 0.20440556 | J7: {=TREND($B7:$C7,$B$3:$C$3,J$3)} -> 0.19093333 | L7: =1/(G7/$G7) -> 1 | M7: =1/(H7/$G7) -> 1 | N7: =1/(I7/$G7) -> 1.0659093 | O7: =1/(J7/$G7) -> 1.1411196
A8: Solid waste, inert | B8: =lcis!C10 -> 0.05562 | C8: =lcis!D10 -> 0.01818 | D8: =(C8-B8)/B8 -> -0.67313916 | E8: =lcis!E10 -> 0.0945 | F8: =(E8-B8)/B8 -> 0.69902913 | G8: =B8 -> 0.05562 | H8: =B8 -> 0.05562 | I8: {=TREND($B8:$C8,$B$3:$C$3,I$3)} -> 0.0369 | J8: {=TREND($B8:$C8,$B$3:$C$3,J$3)} -> 0.01818 | L8: =1/(G8/$G8) -> 1 | M8: =1/(H8/$G8) -> 1 | N8: =1/(I8/$G8) -> 1.5073171 | O8: =1/(J8/$G8) -> 3.0594059
A10: Fuel switch [% MJ heat] | B10: 2025 | C10: 2050 | G10: 2020 | H10: 2025 | I10: 2030 | J10: 2035
A11: Coal | B11: 0.53453274 | C11: 0 | G11: =B11 -> 0.53453274 | H11: =B11 -> 0.53453274 | I11: {=TREND($B11:$C11,$B$10:$C$10,I$10)} -> 0.42762619 | J11: {=TREND($B11:$C11,$B$10:$C$10,J$10)} -> 0.32071965
A12: Natural gas | B12: 0.34007164 | C12: 0.6 | G12: =B12 -> 0.34007164 | H12: =B12 -> 0.34007164 | I12: {=TREND($B12:$C12,$B$10:$C$10,I$10)} -> 0.39205731 | J12: {=TREND($B12:$C12,$B$10:$C$10,J$10)} -> 0.44404299
A13: Waste | B13: 0.075598381 | C13: 0.08 | G13: =B13 -> 0.075598381 | H13: =B13 -> 0.075598381 | I13: {=TREND($B13:$C13,$B$10:$C$10,I$10)} -> 0.076478705 | J13: {=TREND($B13:$C13,$B$10:$C$10,J$10)} -> 0.077359029
A14: Oil | B14: 0.028105014 | C14: 0 | G14: =B14 -> 0.028105014 | H14: =B14 -> 0.028105014 | I14: {=TREND($B14:$C14,$B$10:$C$10,I$10)} -> 0.022484011 | J14: {=TREND($B14:$C14,$B$10:$C$10,J$10)} -> 0.016863008
A15: Biomass | B15: 0.02169222 | C15: 0.32 | G15: =B15 -> 0.02169222 | H15: =B15 -> 0.02169222 | I15: {=TREND($B15:$C15,$B$10:$C$10,I$10)} -> 0.081353776 | J15: {=TREND($B15:$C15,$B$10:$C$10,J$10)} -> 0.14101533
A17: Fuel switch [MJ heat/kg] | B17: 2025 | C17: 2035 | E17: 2035 BAT-Worst | G17: 2020 | H17: 2025 | I17: 2030 | J17: 2035 | L17: 2020 | M17: 2025 | N17: 2030 | O17: 2035
A18: Coal | B18: =B$5*B11 -> 1.9777711 | C18: =C$5*J11 -> 1.0263029 | E18: =E$5*J11 -> 1.3470225 | G18: =B18 -> 1.9777711 | H18: =B18 -> 1.9777711 | I18: {=TREND($B18:$C18,$B$17:$C$17,I$17)} -> 1.502037 | J18: {=TREND($B18:$C18,$B$17:$C$17,J$17)} -> 1.0263029 | L18: =1/(G18/$G18) -> 1 | M18: =1/(H18/$G18) -> 1 | N18: =1/(I18/$G18) -> 1.316726 | O18: =1/(J18/$G18) -> 1.9270833
A19: Natural gas | B19: =B$5*B12 -> 1.2582651 | C19: =C$5*J12 -> 1.4209376 | E19: =E$5*J12 -> 1.8649805 | G19: =B19 -> 1.2582651 | H19: =B19 -> 1.2582651 | I19: {=TREND($B19:$C19,$B$17:$C$17,I$17)} -> 1.3396013 | J19: {=TREND($B19:$C19,$B$17:$C$17,J$17)} -> 1.4209376 | L19: =1/(G19/$G19) -> 1 | M19: =1/(H19/$G19) -> 1 | N19: =1/(I19/$G19) -> 0.93928325 | O19: =1/(J19/$G19) -> 0.88551751
A20: Waste | B20: =B$5*B13 -> 0.27971401 | C20: =C$5*J13 -> 0.24754889 | E20: =E$5*J13 -> 0.32490792 | G20: =B20 -> 0.27971401 | H20: =B20 -> 0.27971401 | I20: {=TREND($B20:$C20,$B$17:$C$17,I$17)} -> 0.26363145 | J20: {=TREND($B20:$C20,$B$17:$C$17,J$17)} -> 0.24754889 | L20: =1/(G20/$G20) -> 1 | M20: =1/(H20/$G20) -> 1 | N20: =1/(I20/$G20) -> 1.0610039 | O20: =1/(J20/$G20) -> 1.1299344
A21: Oil | B21: =B$5*B14 -> 0.10398855 | C21: =C$5*J14 -> 0.053961626 | E21: =E$5*J14 -> 0.070824635 | G21: =B21 -> 0.10398855 | H21: =B21 -> 0.10398855 | I21: {=TREND($B21:$C21,$B$17:$C$17,I$17)} -> 0.078975089 | J21: {=TREND($B21:$C21,$B$17:$C$17,J$17)} -> 0.053961626 | L21: =1/(G21/$G21) -> 1 | M21: =1/(H21/$G21) -> 1 | N21: =1/(I21/$G21) -> 1.316726 | O21: =1/(J21/$G21) -> 1.9270833
A22: Biomass | B22: =B$5*B15 -> 0.080261213 | C22: =C$5*J15 -> 0.45124906 | E22: =E$5*J15 -> 0.59226439 | G22: =B22 -> 0.080261213 | H22: =B22 -> 0.080261213 | I22: {=TREND($B22:$C22,$B$17:$C$17,I$17)} -> 0.26575514 | J22: {=TREND($B22:$C22,$B$17:$C$17,J$17)} -> 0.45124906 | L22: =1/(G22/$G22) -> 1 | M22: =1/(H22/$G22) -> 1 | N22: =1/(I22/$G22) -> 0.3020119 | O22: =1/(J22/$G22) -> 0.17786455
A24: CCS adoption [%] | B24: 2020 | C24: 2030 | D24: 2035 | G24: 2020 | H24: 2025 | I24: 2030 | J24: 2035
A25: Without CCS | B25: 1 | C25: 0.9 | D25: 0.85 | G25: =B25 -> 1 | H25: =B25 -> 1 | I25: =C25 -> 0.9 | J25: =D25 -> 0.85
A26: With CCS | B26: 0 | C26: 0.1 | D26: 0.15 | G26: =B26 -> 0 | H26: =B26 -> 0 | I26: =C26 -> 0.1 | J26: =D26 -> 0.15
A28: soda ash production, Solvay process
A29: LCI parameters | B29: 2025 | C29: 2035 | E29: 2035 BAT-Worst | G29: 2020 | H29: 2025 | I29: 2030 | J29: 2035 | L29: 2020 | M29: 2025 | N29: 2030 | O29: 2035
A30: Limestone consumption | B30: =lcis!C49 -> 1.3 | C30: =lcis!D49 -> 1.1 | D30: =(C30-B30)/B30 -> -0.15384615 | E30: =lcis!E49 -> 1.5 | F30: =(E30-B30)/B30 -> 0.15384615 | G30: =B30 -> 1.3 | H30: =B30 -> 1.3 | I30: {=TREND($B30:$C30,$B$29:$C$29,I$29)} -> 1.2 | J30: {=TREND($B30:$C30,$B$29:$C$29,J$29)} -> 1.1 | L30: =G30/$G30 -> 1 | M30: =1/(H30/$G30) -> 1 | N30: =1/(I30/$G30) -> 1.0833333 | O30: =1/(J30/$G30) -> 1.1818182
A31: Sodium chloride consumption | B31: =lcis!C50 -> 1.6 | C31: =lcis!D50 -> 1.5 | D31: =(C31-B31)/B31 -> -0.0625 | E31: =lcis!E50 -> 1.7 | F31: =(E31-B31)/B31 -> 0.0625 | G31: =B31 -> 1.6 | H31: =B31 -> 1.6 | I31: {=TREND($B31:$C31,$B$29:$C$29,I$29)} -> 1.55 | J31: {=TREND($B31:$C31,$B$29:$C$29,J$29)} -> 1.5 | L31: =G31/$G31 -> 1 | M31: =1/(H31/$G31) -> 1 | N31: =1/(I31/$G31) -> 1.0322581 | O31: =1/(J31/$G31) -> 1.0666667
A32: Ammonia makeup | B32: =lcis!C51 -> 0.00145 | C32: =lcis!D51 -> 0.0008 | D32: =(C32-B32)/B32 -> -0.44827586 | E32: =lcis!E51 -> 0.0021 | F32: =(E32-B32)/B32 -> 0.44827586 | G32: =B32 -> 0.00145 | H32: =B32 -> 0.00145 | I32: {=TREND($B32:$C32,$B$29:$C$29,I$29)} -> 0.001125 | J32: {=TREND($B32:$C32,$B$29:$C$29,J$29)} -> 0.0008 | L32: =G32/$G32 -> 1 | M32: =1/(H32/$G32) -> 1 | N32: =1/(I32/$G32) -> 1.2888889 | O32: =1/(J32/$G32) -> 1.8125
A33: Coke consumption | B33: =lcis!C52 -> 2.3148148 | C33: =lcis!D52 -> 2.037037 | D33: =(C33-B33)/B33 -> -0.12 | E33: =lcis!E52 -> 2.5925926 | F33: =(E33-B33)/B33 -> 0.12 | G33: =B33 -> 2.3148148 | H33: =B33 -> 2.3148148 | I33: {=TREND($B33:$C33,$B$29:$C$29,I$29)} -> 2.1759259 | J33: {=TREND($B33:$C33,$B$29:$C$29,J$29)} -> 2.037037 | L33: =G33/$G33 -> 1 | M33: =1/(H33/$G33) -> 1 | N33: =1/(I33/$G33) -> 1.0638298 | O33: =1/(J33/$G33) -> 1.1363636
A34: Heat consumption | B34: =lcis!C53 -> 7.6388889 | C34: =lcis!D53 -> 6.1111111 | D34: =(C34-B34)/B34 -> -0.2 | E34: =lcis!E53 -> 9.1666667 | F34: =(E34-B34)/B34 -> 0.2 | G34: =B34 -> 7.6388889 | H34: =B34 -> 7.6388889 | I34: {=TREND($B34:$C34,$B$29:$C$29,I$29)} -> 6.875 | J34: {=TREND($B34:$C34,$B$29:$C$29,J$29)} -> 6.1111111 | L34: See below by fuel type
A35: Heat consumption, with CCS | B35: =lcis!C77+lcis!C78 -> 8.5973889 | C35: =lcis!D77+lcis!D78 -> 7.0696111 | D35: =(C35-B35)/B35 -> -0.17770253 | E35: =lcis!E77+lcis!E78 -> 10.316867 | F35: =(E35-B35)/B35 -> 0.2 | G35: =B35 -> 8.5973889 | H35: =B35 -> 8.5973889 | I35: {=TREND($B35:$C35,$B$29:$C$29,I$29)} -> 7.8335 | J35: {=TREND($B35:$C35,$B$29:$C$29,J$29)} -> 7.0696111 | L35: See below by fuel type | R35: =1/0.666666666666666 -> 1.5
A36: Electricity consumption | B36: =lcis!C54 -> 0.09 | C36: =lcis!D54 -> 0.05 | D36: =(C36-B36)/B36 -> -0.44444444 | E36: =lcis!E54 -> 0.13 | F36: =(E36-B36)/B36 -> 0.44444444 | G36: =B36 -> 0.09 | H36: =B36 -> 0.09 | I36: {=TREND($B36:$C36,$B$29:$C$29,I$29)} -> 0.07 | J36: {=TREND($B36:$C36,$B$29:$C$29,J$29)} -> 0.05 | L36: =G36/$G36 -> 1 | M36: =1/(H36/$G36) -> 1 | N36: =1/(I36/$G36) -> 1.2857143 | O36: =1/(J36/$G36) -> 1.8
A37: Electricity consumption, with CCS | B37: =lcis!C79+lcis!C80 -> 0.11925 | C37: =lcis!D79+lcis!D80 -> 0.07925 | D37: =(C37-B37)/B37 -> -0.33542977 | E37: =lcis!E55 -> 0.35 | F37: =(E37-B37)/B37 -> 1.9350105 | G37: =B37 -> 0.11925 | H37: =B37 -> 0.11925 | I37: {=TREND($B37:$C37,$B$29:$C$29,I$29)} -> 0.09925 | J37: {=TREND($B37:$C37,$B$29:$C$29,J$29)} -> 0.07925 | L37: =G37/$G37 -> 1 | M37: =1/(H37/$G37) -> 1 | N37: =1/(I37/$G37) -> 1.2015113 | O37: =1/(J37/$G37) -> 1.5047319 | R37: =Q39*R35 -> 0.00125
A38: Solid waste, inert | B38: =-(lcis!C55+lcis!C56) -> -0.265 | C38: =-(lcis!D55+lcis!D56) -> -0.06 | D38: =(C38-B38)/B38 -> -0.77358491 | E38: =-(lcis!E55+lcis!E56) -> -0.47 | F38: =(E38-B38)/B38 -> 0.77358491 | G38: =B38 -> -0.265 | H38: =B38 -> -0.265 | I38: {=TREND($B38:$C38,$B$29:$C$29,I$29)} -> -0.1625 | J38: {=TREND($B38:$C38,$B$29:$C$29,J$29)} -> -0.06 | L38: =G38/$G38 -> 1 | M38: =1/(H38/$G38) -> 1 | N38: =1/(I38/$G38) -> 1.6307692 | O38: =1/(J38/$G38) -> 4.4166667
A39: Water, withdrawal | B39: =lcis!C64 -> 0.83333333 | C39: =lcis!D64 -> 0.55555556 | D39: =(C39-B39)/B39 -> -0.33333333 | E39: =lcis!E64 -> 1.1111111 | F39: =(E39-B39)/B39 -> 0.33333333 | G39: =B39 -> 0.83333333 | H39: =B39 -> 0.83333333 | I39: {=TREND($B39:$C39,$B$29:$C$29,I$29)} -> 0.69444444 | J39: {=TREND($B39:$C39,$B$29:$C$29,J$29)} -> 0.55555556 | L39: =G39/$G39 -> 1 | M39: =1/(H39/$G39) -> 1 | N39: =1/(I39/$G39) -> 1.2 | O39: =1/(J39/$G39) -> 1.5 | Q39: 0.00083333333 | R39: 0.00024710819 | T39: =1/(R39/Q39) -> 3.372342
A40: Water, cooling | B40: =lcis!C65 -> 69.444444 | C40: =lcis!D65 -> 46.296296 | D40: =(C40-B40)/B40 -> -0.33333333 | E40: =lcis!E65 -> 92.592593 | F40: =(E40-B40)/B40 -> 0.33333333 | G40: =B40 -> 69.444444 | H40: =B40 -> 69.444444 | I40: {=TREND($B40:$C40,$B$29:$C$29,I$29)} -> 57.87037 | J40: {=TREND($B40:$C40,$B$29:$C$29,J$29)} -> 46.296296 | L40: =G40/$G40 -> 1 | M40: =1/(H40/$G40) -> 1 | N40: =1/(I40/$G40) -> 1.2 | O40: =1/(J40/$G40) -> 1.5 | Q40: 0.069444444 | R40: 0.020592349 | T40: =1/(R40/Q40) -> 3.372342
A41: Water, discharge | B41: =lcis!C67 -> 64.685417 | C41: =lcis!D67 -> 42.663426 | D41: =(C41-B41)/B41 -> -0.34044754 | E41: =lcis!E67 -> 86.707407 | F41: =(E41-B41)/B41 -> 0.34044754 | G41: =B41 -> 64.685417 | H41: =B41 -> 64.685417 | I41: {=TREND($B41:$C41,$B$29:$C$29,I$29)} -> 53.674421 | J41: {=TREND($B41:$C41,$B$29:$C$29,J$29)} -> 42.663426 | L41: =G41/$G41 -> 1 | M41: =1/(H41/$G41) -> 1 | N41: =1/(I41/$G41) -> 1.2051442 | O41: =1/(J41/$G41) -> 1.5161796 | Q41: 0.0036016204 | R41: 0.0016019818 | T41: =1/(R41/Q41) -> 2.248228
A42: Water, evaporation | B42: =lcis!C68 -> 3.6016204 | C42: =lcis!D68 -> 2.4291667 | D42: =(C42-B42)/B42 -> -0.32553506 | E42: =lcis!E68 -> 4.7740741 | F42: =(E42-B42)/B42 -> 0.32553506 | G42: =B42 -> 3.6016204 | H42: =B42 -> 3.6016204 | I42: {=TREND($B42:$C42,$B$29:$C$29,I$29)} -> 3.0153935 | J42: {=TREND($B42:$C42,$B$29:$C$29,J$29)} -> 2.4291667 | L42: =G42/$G42 -> 1 | M42: =1/(H42/$G42) -> 1 | N42: =1/(I42/$G42) -> 1.1944114 | O42: =1/(J42/$G42) -> 1.4826568 | Q42: 0.064685417 | R42: 0.028771733 | T42: =1/(R42/Q42) -> 2.248228
A44: Fuel switch [% MJ heat] | B44: 2025 | C44: 2035 | G44: 2020 | H44: 2025 | I44: 2030 | J44: 2035
A45: Coal | B45: 0.6 | C45: 0.05 | G45: =B45 -> 0.6 | H45: =B45 -> 0.6 | I45: {=TREND($B45:$C45,$B$44:$C$44,I$76)} -> 0.325 | J45: {=TREND($B45:$C45,$B$44:$C$44,J$76)} -> 0.05
...

Sheet lcis
A2: quicklime production, PFRK, milled, loose
A3: Parameter | B3: Unit | C3: Baseline | D3: BAT | E3: BAT-Worst | F3: Source | G3: Comment
A4: Limestone | B4: kg/kg quicklime | C4: =AVERAGE(1.4,2.2)*(1+0.03) -> 1.854 | D4: =AVERAGE(1.4,2.2)*(1+0.01) -> 1.818 | E4: =AVERAGE(1.4,2.2)*(1+0.05) -> 1.89 | F4: BREF (2013) | G4: Average limestone fed to the kiln based on the BREF range of 1.4-2.2 kg limestone/kg quicklime. "The calcination of limestone can produce the by-product lime with particulate sizes and decarbonation levels which do not always correspond to the market requirements. This byproduct can be collected directly from the kiln outlet during start-up and shutdown procedures or by the screening or dedusting of the flue-gas. This by-product accounts for 1 to 5 % of the total yearly production." For the min-max range we keep the net input of limestone constant at 1.8 kg and adjust the input to plant based on the 1-5% rejection rate
A5: Heat | B5: MJ/kg quicklime | C5: =AVERAGE(3.2,4.2) -> 3.7 | D5: 3.2 | E5: 4.2 | F5: BREF (2013) | G5: Heat consumption for PFRK ranges from 3.2 to 4.2 MJ/t quicklime (BREF, 2013). We assume an average of 3.7 MJ/t quicklime and 3.2 MJ/t quicklime for BAT. For the min-max range we use the BAT range
A6: Electricity, kiln + screening and sizing | B6: kWh/kg quicklime | C6: =AVERAGE(20+10,40+40)/1000 -> 0.055 | D6: =30/1000 -> 0.03 | E6: 0.08 | F6: BREF (2013) | G6: Electricity use range for PFRK is 20-40 kWh/t lime. Moreover, between 10 and 40 kWh per tonne quicklime are required for the grinding to finer grades (BREF). For the min-max range we use the BAT range
A7: Diesel, burned in building machine | B7: MJ/kg quicklime | C7: CONFIDENTIAL | D7: = | E7: = | F7: ecoinvent v3.10.1 | G7: Diesel used for on-site transportation; confidential ecoinvent data
A8: Factory | B8: unit/kg quicklime | C8: 1.12e-12 | D8: = | E8: = | F8: Foteinis et al. (2022)
A9: Machinery | B9: kg/kg quicklime | C9: 1.61e-05 | D9: = | E9: = | F9: Foteinis et al. (2022)
A10: Waste, inert (fines limestone) | B10: kg/kg quicklime | C10: =C4*0.03 -> 0.05562 | D10: =D4*0.01 -> 0.01818 | E10: =E4*0.05 -> 0.0945 | F10: Estimate | G10: Estimate based on fines limestone production rate
A11: CO2 emissions | B11: kg/kg quicklime | C11: 0.785 | D11: = | E11: = | F11: BREF (2013) | G11: stoichiometric CO2 emission due to calcination (excluding rejected limestone). Since the net input of limestone is kept constant, these emissions do not change
A12: Water, air emission | B12: m3/kg quicklime | C12: CONFIDENTIAL | D12: = | E12: = | F12: ecoinvent v3.10.1 | G12: confidential ecoinvent data, yet very small in the range 10EXP-08
A13: Water, to water bodies | B13: m3/kg quicklime | C13: CONFIDENTIAL | D13: = | E13: = | F13: ecoinvent v3.10.1 | G13: confidential ecoinvent data, yet very small in the range 10EXP-08
A14: quicklime production, PFRK with carbon capture and storage, milled, loose
A15: Parameter | B15: Unit | C15: Baseline | D15: BAT | E15: BAT-Worst | F15: Source | G15: Comment
A16: Limestone | B16: kg/kg quicklime | C16: =C4 -> 1.854 | D16: =D4 -> 1.818 | E16: =E4 -> 1.89 | F16: Conventional process
A17: Heat | B17: MJ/kg quicklime | C17: =C5 -> 3.7 | D17: =D5 -> 3.2 | E17: =E5 -> 4.2 | F17: Conventional process
A18: Electricity, kiln + screening and sizing | B18: kWh/kg quicklime | C18: =C6 -> 0.055 | D18: =D6 -> 0.03 | E18: =E6 -> 0.08 | F18: Conventional process
A19: Electricity, air separation | B19: kWh/kg quicklime | C19: =(262/3.6)/1000 -> 0.072777778 | D19: =(255/3.6)/1000 -> 0.070833333 | E19: =(332/3.6)/1000 -> 0.092222222 | F19: Foteinis et al. (2022) | G19: "the electricity consumption for oxygen production (air separation), which is required for oxyfuel combustion, was assumed to be 262 MJ tCaO 1 (range 255–332 MJ tCaO 1)" (Foteinis et al., 2022). The lower value was assumed as BAT and the range used for the min-max
A20: Electricity, CO2 purification | B20: kWh/kg quicklime | C20: =90.1/1000 -> 0.0901 | D20: =C20 -> 0.0901 | E20: =D20 -> 0.0901 | F20: Foteinis et al. (2022) | G20: "For CO2 purification and capture, prior valorisation or storage, an improved cryogenic separation and distillation system was considered, with the theoretical electricity input for CO2 purification (99.9% purity) and capture being 0.425 MJ kgCO2". Electricity for compression and injection into a geological survey is considered within the corresponding dataset
A21: Diesel, burned in building machine | B21: MJ/kg quicklime | C21: CONFIDENTIAL | D21: = | E21: = | F21: Conventional process
A22: Factory | B22: unit/kg quicklime | C22: =C8 -> 1.12e-12 | D22: = | E22: = | F22: Conventional process
A23: Machinery | B23: kg/kg quicklime | C23: =C9 -> 1.61e-05 | D23: = | E23: = | F23: Conventional process
A24: Waste, inert (fines limestone) | B24: kg/kg quicklime | C24: =C10 -> 0.05562 | D24: =D10 -> 0.01818 | E24: =E10 -> 0.0945 | F24: Conventional process | G24: Estimate based on fines limestone production rate
A25: CO2, captured | B25: kg/kg quicklime | C25: =C11 -> 0.785 | D25: =D11 -> = | E25: = | G25: Assuming 100% capture efficiency
A26: CO2 emissions | B26: kg/kg quicklime | C26: 0 | D26: = | E26: = | G26: Assuming 100% capture efficiency
A27: soda ash production, trona process
A28: Parameter | B28: Unit | C28: Baseline | D28: BAT | E28: BAT-Worst | F28: Source | G28: Comment
A29: Electricity | B29: kWh/kg soda ash | C29: =0.4356/3.6 -> 0.121 | D29: = | E29: = | F29: USLCI
A30: Heat | B30: MJ/kg soda ash | C30: 2.7854154 | D30: =C30*(1-(1-D53/C53)) -> 2.2283323 | E30: =C30 -> 2.7854154 | F30: US EPA (2009) | G30: US EPA (2009): Technical Support Document for the Soda Ash Manufacturing Sector: Proposed Rule for Mandatory Reporting of Greenhouse Gases. Heat consumption is assumed to decrease at the same level as in the Solvay process (i.e., 20%)
A31: Diesel, in machinery | B31: MJ/kg soda ash | C31: =(0.0002828+0.00000112+0.0000617)*38.6 -> 0.013340932 | D31: = | E31: = | F31: USLCI | G31: Gasoline, combusted in equipment + Diesel, combusted in industrial equipment
A32: Quicklime | B32: kg/kg soda ash | C32: =(8.49+12.4)/1000 -> 0.02089 | D32: = | E32: = | F32: USLCI
A33: Activated carbon | B33: kg/kg soda ash | C33: =0.205/1000 -> 0.000205 | D33: = | E33: = | F33: USLCI
A34: CO2, liquid | B34: kg/kg soda ash | C34: =0.1061/1000 -> 0.0001061 | D34: = | E34: = | F34: USLCI
A35: Chlorine | B35: kg/kg soda ash | C35: =0.0364/1000 -> 3.64e-05 | D35: = | E35: =
A36: Cement | B36: kg/soda ash | C36: =(0.616+0.0000218)/1000 -> 0.0006160218 | D36: = | E36: = | F36: USLCI
A37: Steel | B37: kg/soda ash | C37: =(0.000105+2.286)/1000 -> 0.002286105 | D37: = | E37: = | F37: USLCI
A38: Waste, inert | B38: kg/soda ash | C38: =57.9/1000 -> 0.0579 | D38: = | E38: = | F38: USLCI
A39: Tailings, non-sulfidic | B39: kg/soda ash | C39: =160/1000 -> 0.16 | D39: = | E39: = | F39: USLCI
A40: CO2, emissions to air | B40: kg/kg soda ash | C40: 0.138 | D40: = | E40: = | F40: IPCC | G40: CO2 emissions from calcining trona ore; stoichiometric calculation (2006 IPCC Guidelines for National Greenhouse Gas Inventories: https://www.ipcc-nggip.iges.or.jp/efdb/ef_detail.php). US EPA (2009): default emission factor per unit of output either 0.0974 tons of CO2/ton of trona ore consumed or 0.138 tons of CO2/ton soda ash produced. The default emission factor assumes that the fractional purity of each material is 100%.
A41: Water, withdrawal | B41: kg/kg soda ash | C41: =AVERAGE(1.62,2.43) -> 2.025 | D41: =C41*(1-0.15) -> 1.72125 | E41: 2.42 | F41: USLCI, Reichl (2023) | G41: The USLCI dataset reports water withdrawal equal to 4.126 kg/kg soda ash. However, recent industry data suggests lower water intensities in the range from 1.62 to 2.43 kg/kg soda ash (We Soda), while Eti Soda reports 1.61-1.81 kg/kg soda ash for their operations. We use an average intensity of 2.025 kg as baseline, while assuming a 15% decrease in the BAT based on targets from the Wyoming's Trona Industry. For the BAT-Worst we use the upper bound of 2.43 kg
...

Sheet Soda ash_USGS
A1: https://www.usgs.gov/centers/national-minerals-information-center/soda-ash-statistics-and-information
A2: kt/year | B2: Natural soda ash volume | C2: Synthetic soda ash volume | E2: Natural soda ash share | F2: Synthetic soda ash share
A3: 2010 | B3: 12800 | C3: 34700 | E3: =B3/SUM($B3:$C3) -> 0.26947368 | F3: =C3/SUM($B3:$C3) -> 0.73052632
A4: 2011 | B4: 13000 | C4: 38300 | E4: =B4/SUM($B4:$C4) -> 0.25341131 | F4: =C4/SUM($B4:$C4) -> 0.74658869
A5: 2012 | B5: 13900 | C5: 39000 | E5: =B5/SUM($B5:$C5) -> 0.26275992 | F5: =C5/SUM($B5:$C5) -> 0.73724008
A6: 2013 | B6: 14400 | C6: 36900 | E6: =B6/SUM($B6:$C6) -> 0.28070175 | F6: =C6/SUM($B6:$C6) -> 0.71929825
A7: 2014 | B7: 14400 | C7: 36900 | E7: =B7/SUM($B7:$C7) -> 0.28070175 | F7: =C7/SUM($B7:$C7) -> 0.71929825
A8: 2015 | B8: 14200 | C8: 39200 | E8: =B8/SUM($B8:$C8) -> 0.2659176 | F8: =C8/SUM($B8:$C8) -> 0.7340824
A9: 2016 | B9: 14400 | C9: 39200 | E9: =B9/SUM($B9:$C9) -> 0.26865672 | F9: =C9/SUM($B9:$C9) -> 0.73134328
A10: 2017 | B10: 14500 | C10: 39500 | E10: =B10/SUM($B10:$C10) -> 0.26851852 | F10: =C10/SUM($B10:$C10) -> 0.73148148
A11: 2018 | B11: 16000 | C11: 41000 | E11: =B11/SUM($B11:$C11) -> 0.28070175 | F11: =C11/SUM($B11:$C11) -> 0.71929825
A12: 2019 | B12: 15800 | C12: 41000 | E12: =B12/SUM($B12:$C12) -> 0.27816901 | F12: =C12/SUM($B12:$C12) -> 0.72183099
A13: 2020 | B13: 14700 | C13: 40400 | E13: =B13/SUM($B13:$C13) -> 0.26678766 | F13: =C13/SUM($B13:$C13) -> 0.73321234
A14: 2021 | B14: 16000 | C14: 40100 | E14: =B14/SUM($B14:$C14) -> 0.28520499 | F14: =C14/SUM($B14:$C14) -> 0.71479501
... A17: 2024 | B17: 24000 | C17: 49000 | E17: =B17/SUM($B17:$C17) -> 0.32876712 | F17: =C17/SUM($B17:$C17) -> 0.67123288
A19: 2025 | E19: =0.000000000000001*EXP(0.0165*A19) -> 0.32423835 | F19: =1-E19 -> 0.67576165
A20: 2030 | E20: =0.000000000000001*EXP(0.0165*A20) -> 0.35212241 | F20: =1-E20 -> 0.64787759
A21: 2035 | E21: =0.000000000000001*EXP(0.0165*A21) -> 0.38240448 | F21: =1-E21 -> 0.61759552
A22: 2040 | E22: =0.000000000000001*EXP(0.0165*A22) -> 0.41529075 | F22: =1-E22 -> 0.58470925
A23: 2050 | E23: =0.000000000000001*EXP(0.0165*A23) -> 0.48979106 | F23: =1-E23 -> 0.51020894

Sheet Trona soda ash fuel_US EPA
A1: US EPA (2009): Technical Support Document for the Soda Ash Manufacturing Sector: Proposed Rule for Mandatory Reporting of Greenhouse Gases
A2: https://nepis.epa.gov/Exe/ZyNET.exe/P1009F3C.TXT?ZyActionD=ZyDocument&Client=EPA&Index=2006+Thru+2010&Docs=&Query=&Time=&EndTime=&SearchMethod=1&TocRestrict=n&Toc=&TocEntry=&QField=&QFieldYear=&QFieldMonth=&QFieldDay=&IntQFieldOp=0&ExtQFieldOp=0&XmlQuery=&File=D%3A%5Czyfiles%5CIndex%20Data%5C06thru10%5CTxt%5C00000022%5CP1009F3C.txt&User=ANONYMOUS&Password=anonymous&SortMethod=h%7C-&MaximumDocuments=1&FuzzyDegree=0&ImageQuality=r75g8/r75g8/x150y150g16/i425&Display=hpfr&DefSeekPage=x&SearchBack=ZyActionL&Back=ZyActionS&BackDesc=Results%20page&MaximumPages=1&ZyEntry=1&SeekPage=x&ZyPURL
A4: Fuel | B4: Amount | C4: Unit | D4: LHV (MJ/unit) | E4: MJ | H4: MJ/kg soda ash | I4: % MJ
A5: coal | B5: =107.8*0.45359237/1000 -> 0.048897257 | C5: kg | D5: 29 | E5: =B5*D5 -> 1.4180205 | G5: Coal | H5: =E5 -> 1.4180205 | I5: =H5/$H$8 -> 0.59892659
A6: distillate fuel oil | B6: =0.067*3.78541/1000 -> 0.00025362247 | C6: l | D6: 20.8 | E6: =B6*D6 -> 0.0052753474 | G6: Natural gas | H6: =E8 -> 0.91685551 | I6: =H6/$H$8 -> 0.38725051
A7: residual fuel oil | B7: =0.185*3.78541/1000 -> 0.00070030085 | C7: l | D7: 39.2 | E7: =B7*D7 -> 0.027451793 | G7: Oil | H7: =E6+E7 -> 0.032727141 | I7: =H7/$H$8 -> 0.0138229
A8: natural gas | B8: =797.5*0.0283168/1000 -> 0.022582648 | C8: cubic meter | D8: 40.6 | E8: =B8*D8 -> 0.91685551 | H8: =SUM(H5:H7) -> 2.3676031 | I8: =H8/0.85 -> 2.7854154
D9: 39.2 | E9: =B9*D9 -> 0
D10: https://www.engineeringtoolbox.com/fuels-higher-calorific-values-d_169.html | E10: =SUM(E5:E9) -> 2.3676031

Sheet Soda ash Water balance
A1: Water balance in the Solvay process
A3: Unit | B3: kg/kg soda ash (light) | L3: Comment
A4: Activity | B4: Input water | E4: Evaporated water | I4: Wastewater
B5: Baseline | C5: BAT | D5: BAT-Worst | E5: Evaporation ratio | F5: Baseline | G5: BAT | H5: BAT-Worst | I5: Baseline | J5: BAT | K5: BAT-Worst
A6: Process water
A7: Slaking of the lime | B7: =AVERAGE(1.9,2.4)/1.08 -> 1.9907407 | C7: =AVERAGE(1.9)/1.08 -> 1.7592593 | D7: =AVERAGE(2.4)/1.08 -> 2.2222222 | E7: 0.066543847 | F7: =B7*$E$7 -> 0.13247155 | G7: =C7*$E$7 -> 0.11706788 | H7: =D7*$E$7 -> 0.14787521 | I7: - | J7: - | K7: - | L7: Evaporation ratio calculated from the ecoinvent activity "lime production, hydrated, loose, weigt" as the ratio between input water and water emissions to air
A8: Brine purification | B8: - | C8: - | D8: - | E8: - | F8: - | G8: - | H8: - | I8: - | J8: - | K8: - | L8: Water in brine is not considered in the overall water balance
A9: Washing and cooling | B9: =AVERAGE(0.6,1.2)/1.08 -> 0.83333333 | C9: =AVERAGE(0.6)/1.08 -> 0.55555556 | D9: =1.2/1.08 -> 1.1111111 | E9: - | F9: - | G9: - | H9: -
A10: Cooling | B10: =AVERAGE(50,100)/1.08 -> 69.444444 | C10: =50/1.08 -> 46.296296 | D10: =100/1.08 -> 92.592593 | E10: 0.05 | F10: =B10*$E$7 -> 4.6211005 | G10: =C10*$E$7 -> 3.0807336 | H10: =D10*$E$7 -> 6.1614673 | L10: "With regard to cooling water, it was assumed that only 5% of the abstracted water is consumed (evaporated)," (Journal of Cleaner Production 33 (2012) 155e166)… "Generally, it can be said that in industrial cooling towers, between one to five percent of the circulating water in the tower evaporates." (https://www.icib.co/en/news/calculation-of-evaporation-in-the-cooling-tower-a-necessity-for-water-consumption-management)
A12: Solvay ecoinvent
B13: ecoinvent
A14: kg/kg | B14: Input | C14: Output
A15: Water, process | B15: =0.00113*1000 -> 1.13
A16: Water, cooling | B16: =0.0369*1000 -> 36.9
A17: Water, discharge | C17: =0.0235*1000 -> 23.5
A18: Water, evaporation | C18: =0.0145*1000 -> 14.5
A19: Total, inputs | B19: =SUM(B15:B18) -> 38.03
A20: Total, ouputs | C20: =SUM(C15:C18) -> 38
A21: Input product | C21: =B19-C20 -> 0.03
A23: Evaporation rate | B23: =C18/B19 -> 0.38127794
A24: Discharge rate | B24: =C17/B19 -> 0.61793321
A25: Incorporated into the product | B25: =C21/B19 -> 0.00078885091

Sheet Refs
A1: USLCI dataset for trona soda ash | B1: https://lcacommons.gov/lca-collaboration/National_Renewable_Energy_Laboratory/USLCI_Database_Public/dataset/PROCESS/0d95cc8b-a9a0-3630-a760-1ab4d88257d8?commitId=7d7143983462ce7c48bf8d64bccbe5cafda11c45?gladview=true
A2: Reichl (2023) | B2: https://csgwest.org/wp-content/uploads/2023/10/Industrial-Water-Challenges-Trona-CGS-West-2023-09-14-Final.pdf
A3: We Soda | B3: https://wesoda.com/documents/we-soda-ensuring-sustainable-soda-ash-supply-2022
A4: Eti Soda | B4: https://www.etisoda.com/wp-content/uploads/2022/12/Eti-Soda-S.R.-2021-EN-1.pdf
